Traceback (most recent call last):
  File "/home/andretelfer/anaconda3/lib/python3.9/site-packages/jupyter_cache/executors/utils.py", line 51, in single_nb_execution
    executenb(
  File "/home/andretelfer/anaconda3/lib/python3.9/site-packages/nbclient/client.py", line 1204, in execute
    return NotebookClient(nb=nb, resources=resources, km=km, **kwargs).execute()
  File "/home/andretelfer/anaconda3/lib/python3.9/site-packages/nbclient/util.py", line 84, in wrapped
    return just_run(coro(*args, **kwargs))
  File "/home/andretelfer/anaconda3/lib/python3.9/site-packages/nbclient/util.py", line 62, in just_run
    return loop.run_until_complete(coro)
  File "/home/andretelfer/anaconda3/lib/python3.9/asyncio/base_events.py", line 647, in run_until_complete
    return future.result()
  File "/home/andretelfer/anaconda3/lib/python3.9/site-packages/nbclient/client.py", line 663, in async_execute
    await self.async_execute_cell(
  File "/home/andretelfer/anaconda3/lib/python3.9/site-packages/nbclient/client.py", line 965, in async_execute_cell
    await self._check_raise_for_error(cell, cell_index, exec_reply)
  File "/home/andretelfer/anaconda3/lib/python3.9/site-packages/nbclient/client.py", line 862, in _check_raise_for_error
    raise CellExecutionError.from_cell_and_msg(cell, exec_reply_content)
nbclient.exceptions.CellExecutionError: An error occurred while executing the following cell:
------------------
all_vertices = []

for idx, p in enumerate(sorted(LABEL_DIR.glob("*.txt"))):
    with open(p, 'r') as fp:
        lines = fp.readlines()
    
    # Turn the data into a dataframe
    data = [l.strip().split(' ') for l in lines]
    df = pd.DataFrame(data, columns=['0', 'x', 'y', 'w', 'h', 'c']).astype(float)

    # Drop low confidence frames
    df = df[df.c > 0.2]
    
    # Scale by image size
    fname, _ = p.parts[-1].split('.')
    image = imread(DATA_DIR / f"{fname}.png")
    h, w, c = image.shape
    df.y *= h
    df.h *= h
    df.x *= w
    df.w *= w
    
    # Get x,y vertices for rectangle
    i = np.ones(shape=df.shape[0])*idx
    vertices = np.array([
        [i, df.y-df.h/2, df.x-df.w/2],
        [i, df.y+df.h/2, df.x-df.w/2],
        [i, df.y+df.h/2, df.x+df.w/2],
        [i, df.y-df.h/2, df.x+df.w/2]
    ]).transpose(2, 0, 1)
    all_vertices.append(vertices)
    
all_vertices = np.concatenate(all_vertices)
------------------

[0;31m---------------------------------------------------------------------------[0m
[0;31mNameError[0m                                 Traceback (most recent call last)
Input [0;32mIn [8][0m, in [0;36m<cell line: 3>[0;34m()[0m
[1;32m      1[0m all_vertices [38;5;241m=[39m []
[0;32m----> 3[0m [38;5;28;01mfor[39;00m idx, p [38;5;129;01min[39;00m [38;5;28menumerate[39m([38;5;28msorted[39m([43mLABEL_DIR[49m[38;5;241m.[39mglob([38;5;124m"[39m[38;5;124m*.txt[39m[38;5;124m"[39m))):
[1;32m      4[0m     [38;5;28;01mwith[39;00m [38;5;28mopen[39m(p, [38;5;124m'[39m[38;5;124mr[39m[38;5;124m'[39m) [38;5;28;01mas[39;00m fp:
[1;32m      5[0m         lines [38;5;241m=[39m fp[38;5;241m.[39mreadlines()

[0;31mNameError[0m: name 'LABEL_DIR' is not defined
NameError: name 'LABEL_DIR' is not defined

